Workbook

Sheet Guide
A1: Isocyanate Conversion Workbook — DSC · FTIR · DMA · TMA
A2: Estimates NCO conversion (α) for urethane-forming systems by four independent techniques and compares them sample-by-sample.
A4: SHEET MAP — click a name to jump to that sheet's instructions
A5: Sample_Prep ▸ | B5: Read before mixing: one batch, matched specimens, and how to make and measure the specimen behind every value.
A6: Formulation ▸ | B6: Start here: stoichiometry, %NCO, gel point and the network model the other sheets use.
A7: DSC ▸ | B7: Conversion from residual exotherm (measured or theoretical total heat), plus an optional Tg route.
A8: DSC_Isothermal ▸ | B8: DSC only: α(t) and dα/dt from one isothermal hold plus a residual scan on the same specimen.
A9: FTIR ▸ | B9: Conversion from the NCO band at ~2270 cm⁻¹ normalised to an unchanging reference band.
A10: DMA ▸ | B10: Crosslink density from the rubbery-plateau modulus, and conversion from it and from tan δ Tg.
A11: TMA ▸ | B11: Conversion from the expansion Tg (tangent intersection) and from the rubbery compression modulus.
A12: Summary ▸ | B12: Every method side by side by sample ID, with mean, spread and an agreement flag.
A13: MM_Table ▸ | B13: Calculation sheet behind the DMA and TMA modulus conversions (no inputs).
A14: Lambda_Fit ▸ | B14: Calculation sheet: least-squares λ for the DiBenedetto Tg routes on DSC, DMA and TMA (no inputs).
A16: HOW THE SHEETS CONNECT
A46: CELL LEGEND
A47: Blue text, yellow fill | B47: Input — type your data here. Every yellow cell is editable; nothing else needs touching.
A48: Black text, grey fill | B48: Calculated — do not overwrite.
A49: Green text, grey fill | B49: Pulled from another sheet (mostly Formulation).
A50: Example data | B50: Rows S0–S4 on every sheet are a worked example (PPG triol, EW 1000, f = 3 + IPDI, index 100, cured at 60 °C). Overwrite or clear them.
A52: WORKFLOW
A53: 0. Sample_Prep | B53: Plan the batch before mixing: one mix, matched specimens for every technique, cured together, the same Sample ID on every sheet.
A54: 1. Formulation | B54: Enter masses, equivalent weights, functionalities and density. This sets NCO:OH ratio r, initial %NCO, the gel point and the network model used by DMA and TMA.
A55: 2. DSC | B55: Enter the uncured reference scan(s), then the residual exotherm (and optionally Tg) for each partially cured sample. Choose the ΔH_total basis in E14: Measured reference, or Theoretical (formulation) when no fresh-mix reference scan exists.
A56: 2b. DSC_Isothermal | B56: DSC-only kinetics on one specimen: paste the isothermal heat-flow export (time, W/g), enter the baseline and the residual heat from a dynamic scan run afterwards. Gives α(t) and dα/dt.
A57: DSC on its own | B57: Every DSC result is independent of FTIR, DMA and TMA — leave those sheets blank if you have no data; the Summary simply shows blanks for them.
A58: 3. FTIR | B58: Row 11 MUST be the t = 0 (uncured) spectrum. Enter integrated NCO and reference-band areas for every time point.
A59: 4. DMA | B59: Enter rubbery-plateau E′ and the temperature it was read at, plus tan δ peak Tg. Pre-gel samples cannot be measured — leave them out.
A60: 4b. TMA | B60: Route 1: tangent points (or the instrument's Tg) from the expansion curve. Route 2: two force/deformation points in compression at ≥ Tg + 30 °C. Post-gel specimens only.
A61: 5. Summary | B61: Type sample IDs in column A; α from every method is pulled in by ID (IDs must match exactly across sheets).
A63: EQUATIONS
A64: DSC — residual heat | B64: α = 1 − ΔH_res / ΔH_total, both normalised per gram of reactive resin (ΔH per g sample ÷ reactive mass fraction w_r) so plasticiser/filler dilution cancels.
A65: DSC — ΔH_total options | B65: (a) Measured: complete dynamic scan of freshly mixed material. (b) Theoretical: ΔH_theo = n_NCO · ΔH_urethane / m_total (J/g), no reference scan. (c) Isothermal + residual: ΔH_total = Q_iso + Q_res on the same specimen.
A66: DSC — isothermal | B66: Q(t) = ∫ s·[q(t) − q_baseline] dt (trapezoid, s = ±1 for exo direction); α(t) = Q(t)/ΔH_total; dα/dt = s·[q − q_baseline]/ΔH_total.
B67: The reference scan also yields an experimental urethane enthalpy, ΔH_total / (mol NCO per g) — use it to calibrate option (b) for later batches.
A68: Tg routes (DSC/DMA/TMA) | B68: DiBenedetto (Pascault–Williams form): (Tg − Tg0)/(Tg∞ − Tg0) = λα / [1 − (1 − λ)α], λ ≈ ΔCp∞/ΔCp0. Inverted: α = x / [λ + x(1 − λ)], x = (Tg − Tg0)/(Tg∞ − Tg0). Tg0, Tg∞ and λ must come from the same technique as the sample Tg (DSC midpoint vs DMA tan δ peak differ by ~5–20 °C).
B69: λ is chosen per sheet: least-squares fit to residual-heat α (default; see Lambda_Fit), the measured ΔCp ratio, the Tg0/Tg∞ (kelvin) estimate, or a manual value.
A70: FTIR | B70: α = 1 − (A_NCO/A_ref)_t / (A_NCO/A_ref)_0. NCO asymmetric stretch ≈ 2270 cm⁻¹ (integrate ~2230–2300). Reference band must not change during cure (C–H stretch 2870–2970 cm⁻¹, or aromatic C=C ~1595 cm⁻¹ for MDI/TDI). Never use C=O or N–H — they grow with urethane formation.
A71: DMA — modulus route | B71: Rubber elasticity: E′ = 3φ ν_e R T → ν_e = E′ / (3φRT); Mc = ρ/ν_e. Affine φ = 1; phantom φ = 1 − 2/f.
B72: Miller–Macosko for A2 + Bf (one difunctional component, crosslinker f = 3 or 4). With k = r α² (r = NCO/OH, α = NCO conversion), P(F_out) = b solves b = k b^(f−1) + 1 − k:
B73: f = 3: b = (1 − k)/k for k > 1/2 f = 4: b = [−k + √(4k − 3k²)]/(2k) for k > 1/3 (b = 1 below the gel point)
...

Sheet Sample_Prep
A1: Sample preparation — the specimen behind every value
A2: One batch, matched specimens, the same Sample ID on every sheet. Settings are typical starting points; adapt them to your instrument and material.
A3: ↩ Back to the Guide
A5: THE ONE-BATCH WORKFLOW
A29: BEFORE YOU START — applies to every technique
A30: Step | B30: What to do | C30: How | D30: Why it matters | E30: Standard
A31: 1 | B31: Dry the polyol | C31: 2–4 h at 80–100 °C under vacuum (or as the supplier advises); check water by Karl Fischer and keep it below ~0.05 %. | D31: Water consumes NCO (urea + CO₂): FTIR then sees NCO loss with no urethane heat, and bubbles spoil DMA/TMA specimens. | E31: ASTM D4672
A32: 2 | B32: Check the raw materials | C32: Titrate the OH number of the polyol lot and the %NCO of the isocyanate lot; enter those, not nominal values, on Formulation. | D32: Index, gel point, %NCO and theoretical ΔH all depend on them. | E32: ASTM D4274, D2572
A33: 3 | B33: Make one batch | C33: Weigh to the target index on an analytical balance and record the actual masses; add catalyst last; mix 1–2 min in a centrifugal mixer, under vacuum if available. | D33: Every technique then measures the same material — the Summary comparison only means something this way.
A34: 4 | B34: Start the clock | C34: t = 0 is first contact of polyol and isocyanate. Note it, and the time each specimen goes into the oven or instrument. | D34: Cure time is the x-axis of every comparison.
A35: 5 | B35: Split at once | C35: Within a few minutes fill DSC pans, cast FTIR films, pour DMA bars and TMA discs (table below). Measure the t = 0 set straight away. | D35: The mix keeps reacting at room temperature; delays shift t = 0 and lower the measured ΔH_total.
A36: 6 | B36: Cure together | C36: Put every specimen in the same oven at the same time. At each time point pull one of each type and give them the same Sample ID. | D36: Identical thermal history makes the techniques comparable.
A37: 7 | B37: Stop and store | C37: Test at once, or freeze at ≤ −20 °C (−80 °C is better) in a sealed, desiccated bag; let it reach room temperature before opening. | D37: Cold well below Tg stops the reaction; opening a cold bag condenses water on the specimen.
A38: 8 | B38: Measure gently | C38: Keep heating ramps short and, where possible, below the cure temperature; note the maximum temperature each specimen saw. | D38: A partly cured specimen keeps curing while it is heated, which biases α high.
A40: VALUE BY VALUE — which specimen gives each input, and how to measure it
A41: Sheet | B41: Value (cells) | C41: Specimen and how to prepare it | D41: How to measure it | E41: Standard
A42: Formulation | B42: Polyol equivalent weight (B5) | C42: A sample of the polyol lot, dried as in step 1. | D42: OH number by titration; EW = 56100 / OH number. | E42: ASTM D4274
A43: Formulation | B43: Isocyanate equivalent weight (B8) | C43: A sample of the isocyanate lot, handled under dry N₂ (it reacts with air moisture). | D43: %NCO by di-n-butylamine back-titration; EW = 4202 / %NCO. | E43: ASTM D2572
A44: Formulation | B44: Masses (B4, B7, B10) | C44: The batch itself. | D44: Analytical balance, weigh by difference; enter the actual masses, not the targets.
A45: Formulation | B45: Cured density (B11) | C45: A void-free, fully cured piece cast alongside the DMA/TMA specimens. | D45: Buoyancy (Archimedes) in water or another liquid that does not swell it, or gas pycnometry. | E45: ASTM D792
A46: DSC | B46: Reference ΔH_total (C5–C7) | C46: 5–10 mg of fresh mix in a hermetic aluminium pan, sealed and weighed within minutes of mixing; 2–3 replicates. | D46: Cool to ~Tg0 − 30 °C, heat 10 K/min through the whole exotherm under N₂ (50 mL/min); check by TGA that the upper limit is below any mass loss. Integrate with a linear baseline. | E46: ASTM E2160
A47: DSC | B47: Residual ΔH_res (column E) | C47: Best: seal 5–10 mg pans of fresh mix at t = 0 and cure them in the oven with the other specimens. Otherwise cut 5–10 mg from the bulk specimen pulled at that time. | D47: Exactly the same pan type, heating rate, range and baseline as the reference. | E47: ASTM E2160
A48: DSC | B48: Tg midpoint (column I) and Tg0 (B18) | C48: The same pans. For Tg0 use a fresh-mix pan quenched below Tg first. | D48: Midpoint of the step on the first heat, read before the residual exotherm begins. | E48: ASTM E1356
A49: DSC | B49: Tg∞ (B19) and ΔCp∞ (H18) | C49: A pan cured to completion: post-cure until no residual exotherm remains. | D49: Second heat after a complete scan: step midpoint and step height (J/g·K). | E49: ASTM E1356
A50: DSC | B50: ΔCp0 (G18) | C50: The fresh-mix reference pan. | D50: Step height at Tg0 on the first heat (J/g·K). | E50: ASTM E1356
A51: DSC_Isothermal | B51: Heat flow vs time (A27 down) | C51: 5–10 mg of fresh mix in a hermetic pan, loaded as fast as possible after mixing. | D51: Pre-equilibrate the cell at the cure temperature and drop the pan in (or jump at the maximum rate); hold until the signal is flat; export W/g against minutes. Record the delay from mixing to the start.
A52: DSC_Isothermal | B52: Baseline (B8) | C52: The same pan after the run. | D52: Repeat the identical isothermal program on the now-cured pan; its signal is the baseline.
A53: DSC_Isothermal | B53: Residual heat Q_res (B9) | C53: The same pan. | D53: Cool below Tg, then heat 10 K/min through the residual exotherm. | E53: ASTM E2160
A54: FTIR | B54: A_NCO and A_ref at t = 0 (row 11) | C54: A drop of fresh mix. | D54: ATR: a thin layer over the crystal (a heated ATR at the cure temperature gives continuous kinetics). Transmission: a 10–25 µm film between KBr or NaCl so the NCO band stays below ~1 absorbance.
A55: FTIR | B55: A_NCO and A_ref at time t (columns D–E) | C55: A thin film (~0.1–0.5 mm) cast on PTFE or release liner from the same batch and cured with the other specimens. | D55: Same crystal, clamp pressure, 4 cm⁻¹ resolution and 32 scans every time; fresh background each session. Measure the face that was against the liner — the air side also reacts with humidity.
A56: DMA | B56: E′, T at E′ and tan δ peak (columns D–F) | C56: Bars cast in PTFE or silicone moulds from the degassed batch, e.g. 30 × 6 × 1–2 mm (film tension) or 50 × 10 × 3 mm (single cantilever); thickness measured at three points. | D56: Strain sweep first to find the linear region; then 1 Hz, 2–3 K/min from ~Tg − 30 °C to Tg + 50 °C. Read E′ at ≥ Tg + 30 °C; tan δ peak = Tg. Post-gel (handleable) specimens only. | E56: ASTM D4065, E1640
A57: DMA | B57: Tg0 and Tg∞ (B13–B14) | C57: Tg∞: a bar post-cured to completion. Tg0: the liquid cannot be clamped. | D57: Tg∞ by the same ramp. Tg0: extrapolate the Tg–time trend, or use DSC Tg0 plus your DSC→tan δ offset. | E57: ASTM E1640
A58: TMA | B58: Tangent points or Tg (Route 1, columns D–M) | C58: A disc or flat piece 1–3 mm thick and 5–8 mm across with flat, parallel faces (cast in a mould, or cut and lightly sanded). | D58: Expansion probe, small force (~0.02–0.05 N) so it does not sink in above Tg; cool to ~Tg − 40 °C, heat 3–5 K/min. Pick two points on each straight segment, or enter the instrument's Tg in column E. | E58: ASTM E831, E1545
A59: TMA | B59: Forces and deformations (Route 2, columns D–J) | C59: A cylinder or disc smaller than the flat probe (e.g. Ø5 × 2 mm under a Ø6 mm probe); thin silicone oil or PTFE film on both faces so it does not barrel; thickness and diameter by micrometer. | D59: Equilibrate at ≥ Tg + 30 °C; apply a small preload (force 1), then a higher force (force 2) or a slow force ramp; keep compression below 20 %.
A60: TMA | B60: Tg0 and Tg∞ (B13–B14) | C60: Tg0: fresh mix quenched below Tg in a TMA pan. Tg∞: a fully post-cured disc. | D60: Same expansion program; for Tg0 the probe sinks where the material softens — take the onset. | E60: ASTM E1545
A62: Standards are listed for method guidance — check the current edition and your laboratory's own procedures.

Sheet Summary
A1: Summary — NCO conversion by method
A2: Type sample IDs in column A; values are looked up by ID from each method sheet. ▸ How to use this sheet: column O
A3: Agreement tolerance (α range) | D3: 0.05
A5: Sample ID | B5: Cure time (h) | C5: α DSC (residual heat) | D5: α DSC (Tg) | E5: α FTIR | F5: α DMA (Miller–Macosko) | G5: α DMA (tan δ Tg) | H5: α TMA (expansion Tg) | I5: α TMA (compression) | J5: Mean α | K5: Std. dev. | L5: Range | M5: Agreement | O5: HOW TO USE — Summary
A6: S0 | B6: =IF(A6="","",IFERROR(INDEX(DSC!$C$23:$C$42,MATCH(A6,DSC!$A$23:$A$42,0)),IFERROR(INDEX(FTIR!$C$11:$C$35,MATCH(A6,FTIR!$A$11:$A$35,0)),IFERROR(INDEX(DMA!$C$18:$C$37,MATCH(A6,DMA!$A$18:$A$37,0)),IFERROR(INDEX(TMA!$C$20:$C$39,MATCH(A6,TMA!$A$20:$A$39,0)),IFERROR(INDEX(TMA!$C$43:$C$62,MATCH(A6,TMA!$A$43:$A$62,0)),"")))))) | C6: =IF($A6="","",IFERROR(INDEX(DSC!$H$23:$H$42,MATCH($A6,DSC!$A$23:$A$42,0)),"")) | D6: =IF($A6="","",IFERROR(INDEX(DSC!$K$23:$K$42,MATCH($A6,DSC!$A$23:$A$42,0)),"")) | E6: =IF($A6="","",IFERROR(INDEX(FTIR!$H$11:$H$35,MATCH($A6,FTIR!$A$11:$A$35,0)),"")) | F6: =IF($A6="","",IFERROR(INDEX(DMA!$K$18:$K$37,MATCH($A6,DMA!$A$18:$A$37,0)),"")) | G6: =IF($A6="","",IFERROR(INDEX(DMA!$L$18:$L$37,MATCH($A6,DMA!$A$18:$A$37,0)),"")) | H6: =IF($A6="","",IFERROR(INDEX(TMA!$S$20:$S$39,MATCH($A6,TMA!$A$20:$A$39,0)),"")) | I6: =IF($A6="","",IFERROR(INDEX(TMA!$T$43:$T$62,MATCH($A6,TMA!$A$43:$A$62,0)),"")) | J6: =IF(COUNT(C6:I6)=0,"",AVERAGE(C6:I6)) | K6: =IF(COUNT(C6:I6)<2,"",STDEV(C6:I6)) | L6: =IF(COUNT(C6:I6)<2,"",MAX(C6:I6)-MIN(C6:I6)) | M6: =IF(COUNT(C6:I6)<2,"",IF(L6>$D$3,"Methods disagree","Consistent")) | O6: ↩ Back to the Guide
A7: S1 | B7: =IF(A7="","",IFERROR(INDEX(DSC!$C$23:$C$42,MATCH(A7,DSC!$A$23:$A$42,0)),IFERROR(INDEX(FTIR!$C$11:$C$35,MATCH(A7,FTIR!$A$11:$A$35,0)),IFERROR(INDEX(DMA!$C$18:$C$37,MATCH(A7,DMA!$A$18:$A$37,0)),IFERROR(INDEX(TMA!$C$20:$C$39,MATCH(A7,TMA!$A$20:$A$39,0)),IFERROR(INDEX(TMA!$C$43:$C$62,MATCH(A7,TMA!$A$43:$A$62,0)),"")))))) | C7: =IF($A7="","",IFERROR(INDEX(DSC!$H$23:$H$42,MATCH($A7,DSC!$A$23:$A$42,0)),"")) | D7: =IF($A7="","",IFERROR(INDEX(DSC!$K$23:$K$42,MATCH($A7,DSC!$A$23:$A$42,0)),"")) | E7: =IF($A7="","",IFERROR(INDEX(FTIR!$H$11:$H$35,MATCH($A7,FTIR!$A$11:$A$35,0)),"")) | F7: =IF($A7="","",IFERROR(INDEX(DMA!$K$18:$K$37,MATCH($A7,DMA!$A$18:$A$37,0)),"")) | G7: =IF($A7="","",IFERROR(INDEX(DMA!$L$18:$L$37,MATCH($A7,DMA!$A$18:$A$37,0)),"")) | H7: =IF($A7="","",IFERROR(INDEX(TMA!$S$20:$S$39,MATCH($A7,TMA!$A$20:$A$39,0)),"")) | I7: =IF($A7="","",IFERROR(INDEX(TMA!$T$43:$T$62,MATCH($A7,TMA!$A$43:$A$62,0)),"")) | J7: =IF(COUNT(C7:I7)=0,"",AVERAGE(C7:I7)) | K7: =IF(COUNT(C7:I7)<2,"",STDEV(C7:I7)) | L7: =IF(COUNT(C7:I7)<2,"",MAX(C7:I7)-MIN(C7:I7)) | M7: =IF(COUNT(C7:I7)<2,"",IF(L7>$D$3,"Methods disagree","Consistent")) | O7: 1 Type each sample ID in column A exactly as it appears on the method sheets.
A8: S2 | B8: =IF(A8="","",IFERROR(INDEX(DSC!$C$23:$C$42,MATCH(A8,DSC!$A$23:$A$42,0)),IFERROR(INDEX(FTIR!$C$11:$C$35,MATCH(A8,FTIR!$A$11:$A$35,0)),IFERROR(INDEX(DMA!$C$18:$C$37,MATCH(A8,DMA!$A$18:$A$37,0)),IFERROR(INDEX(TMA!$C$20:$C$39,MATCH(A8,TMA!$A$20:$A$39,0)),IFERROR(INDEX(TMA!$C$43:$C$62,MATCH(A8,TMA!$A$43:$A$62,0)),"")))))) | C8: =IF($A8="","",IFERROR(INDEX(DSC!$H$23:$H$42,MATCH($A8,DSC!$A$23:$A$42,0)),"")) | D8: =IF($A8="","",IFERROR(INDEX(DSC!$K$23:$K$42,MATCH($A8,DSC!$A$23:$A$42,0)),"")) | E8: =IF($A8="","",IFERROR(INDEX(FTIR!$H$11:$H$35,MATCH($A8,FTIR!$A$11:$A$35,0)),"")) | F8: =IF($A8="","",IFERROR(INDEX(DMA!$K$18:$K$37,MATCH($A8,DMA!$A$18:$A$37,0)),"")) | G8: =IF($A8="","",IFERROR(INDEX(DMA!$L$18:$L$37,MATCH($A8,DMA!$A$18:$A$37,0)),"")) | H8: =IF($A8="","",IFERROR(INDEX(TMA!$S$20:$S$39,MATCH($A8,TMA!$A$20:$A$39,0)),"")) | I8: =IF($A8="","",IFERROR(INDEX(TMA!$T$43:$T$62,MATCH($A8,TMA!$A$43:$A$62,0)),"")) | J8: =IF(COUNT(C8:I8)=0,"",AVERAGE(C8:I8)) | K8: =IF(COUNT(C8:I8)<2,"",STDEV(C8:I8)) | L8: =IF(COUNT(C8:I8)<2,"",MAX(C8:I8)-MIN(C8:I8)) | M8: =IF(COUNT(C8:I8)<2,"",IF(L8>$D$3,"Methods disagree","Consistent")) | O8: 2 α from every method fills in automatically; a blank means no data on that sheet.
A9: S3 | B9: =IF(A9="","",IFERROR(INDEX(DSC!$C$23:$C$42,MATCH(A9,DSC!$A$23:$A$42,0)),IFERROR(INDEX(FTIR!$C$11:$C$35,MATCH(A9,FTIR!$A$11:$A$35,0)),IFERROR(INDEX(DMA!$C$18:$C$37,MATCH(A9,DMA!$A$18:$A$37,0)),IFERROR(INDEX(TMA!$C$20:$C$39,MATCH(A9,TMA!$A$20:$A$39,0)),IFERROR(INDEX(TMA!$C$43:$C$62,MATCH(A9,TMA!$A$43:$A$62,0)),"")))))) | C9: =IF($A9="","",IFERROR(INDEX(DSC!$H$23:$H$42,MATCH($A9,DSC!$A$23:$A$42,0)),"")) | D9: =IF($A9="","",IFERROR(INDEX(DSC!$K$23:$K$42,MATCH($A9,DSC!$A$23:$A$42,0)),"")) | E9: =IF($A9="","",IFERROR(INDEX(FTIR!$H$11:$H$35,MATCH($A9,FTIR!$A$11:$A$35,0)),"")) | F9: =IF($A9="","",IFERROR(INDEX(DMA!$K$18:$K$37,MATCH($A9,DMA!$A$18:$A$37,0)),"")) | G9: =IF($A9="","",IFERROR(INDEX(DMA!$L$18:$L$37,MATCH($A9,DMA!$A$18:$A$37,0)),"")) | H9: =IF($A9="","",IFERROR(INDEX(TMA!$S$20:$S$39,MATCH($A9,TMA!$A$20:$A$39,0)),"")) | I9: =IF($A9="","",IFERROR(INDEX(TMA!$T$43:$T$62,MATCH($A9,TMA!$A$43:$A$62,0)),"")) | J9: =IF(COUNT(C9:I9)=0,"",AVERAGE(C9:I9)) | K9: =IF(COUNT(C9:I9)<2,"",STDEV(C9:I9)) | L9: =IF(COUNT(C9:I9)<2,"",MAX(C9:I9)-MIN(C9:I9)) | M9: =IF(COUNT(C9:I9)<2,"",IF(L9>$D$3,"Methods disagree","Consistent")) | O9: 3 D3 sets the agreement tolerance (default 5 percentage points).
A10: S4 | B10: =IF(A10="","",IFERROR(INDEX(DSC!$C$23:$C$42,MATCH(A10,DSC!$A$23:$A$42,0)),IFERROR(INDEX(FTIR!$C$11:$C$35,MATCH(A10,FTIR!$A$11:$A$35,0)),IFERROR(INDEX(DMA!$C$18:$C$37,MATCH(A10,DMA!$A$18:$A$37,0)),IFERROR(INDEX(TMA!$C$20:$C$39,MATCH(A10,TMA!$A$20:$A$39,0)),IFERROR(INDEX(TMA!$C$43:$C$62,MATCH(A10,TMA!$A$43:$A$62,0)),"")))))) | C10: =IF($A10="","",IFERROR(INDEX(DSC!$H$23:$H$42,MATCH($A10,DSC!$A$23:$A$42,0)),"")) | D10: =IF($A10="","",IFERROR(INDEX(DSC!$K$23:$K$42,MATCH($A10,DSC!$A$23:$A$42,0)),"")) | E10: =IF($A10="","",IFERROR(INDEX(FTIR!$H$11:$H$35,MATCH($A10,FTIR!$A$11:$A$35,0)),"")) | F10: =IF($A10="","",IFERROR(INDEX(DMA!$K$18:$K$37,MATCH($A10,DMA!$A$18:$A$37,0)),"")) | G10: =IF($A10="","",IFERROR(INDEX(DMA!$L$18:$L$37,MATCH($A10,DMA!$A$18:$A$37,0)),"")) | H10: =IF($A10="","",IFERROR(INDEX(TMA!$S$20:$S$39,MATCH($A10,TMA!$A$20:$A$39,0)),"")) | I10: =IF($A10="","",IFERROR(INDEX(TMA!$T$43:$T$62,MATCH($A10,TMA!$A$43:$A$62,0)),"")) | J10: =IF(COUNT(C10:I10)=0,"",AVERAGE(C10:I10)) | K10: =IF(COUNT(C10:I10)<2,"",STDEV(C10:I10)) | L10: =IF(COUNT(C10:I10)<2,"",MAX(C10:I10)-MIN(C10:I10)) | M10: =IF(COUNT(C10:I10)<2,"",IF(L10>$D$3,"Methods disagree","Consistent")) | O10: 4 Columns J–L: mean, standard deviation and range of the methods that have data.
B11: =IF(A11="","",IFERROR(INDEX(DSC!$C$23:$C$42,MATCH(A11,DSC!$A$23:$A$42,0)),IFERROR(INDEX(FTIR!$C$11:$C$35,MATCH(A11,FTIR!$A$11:$A$35,0)),IFERROR(INDEX(DMA!$C$18:$C$37,MATCH(A11,DMA!$A$18:$A$37,0)),IFERROR(INDEX(TMA!$C$20:$C$39,MATCH(A11,TMA!$A$20:$A$39,0)),IFERROR(INDEX(TMA!$C$43:$C$62,MATCH(A11,TMA!$A$43:$A$62,0)),"")))))) | C11: =IF($A11="","",IFERROR(INDEX(DSC!$H$23:$H$42,MATCH($A11,DSC!$A$23:$A$42,0)),"")) | D11: =IF($A11="","",IFERROR(INDEX(DSC!$K$23:$K$42,MATCH($A11,DSC!$A$23:$A$42,0)),"")) | E11: =IF($A11="","",IFERROR(INDEX(FTIR!$H$11:$H$35,MATCH($A11,FTIR!$A$11:$A$35,0)),"")) | F11: =IF($A11="","",IFERROR(INDEX(DMA!$K$18:$K$37,MATCH($A11,DMA!$A$18:$A$37,0)),"")) | G11: =IF($A11="","",IFERROR(INDEX(DMA!$L$18:$L$37,MATCH($A11,DMA!$A$18:$A$37,0)),"")) | H11: =IF($A11="","",IFERROR(INDEX(TMA!$S$20:$S$39,MATCH($A11,TMA!$A$20:$A$39,0)),"")) | I11: =IF($A11="","",IFERROR(INDEX(TMA!$T$43:$T$62,MATCH($A11,TMA!$A$43:$A$62,0)),"")) | J11: =IF(COUNT(C11:I11)=0,"",AVERAGE(C11:I11)) | K11: =IF(COUNT(C11:I11)<2,"",STDEV(C11:I11)) | L11: =IF(COUNT(C11:I11)<2,"",MAX(C11:I11)-MIN(C11:I11)) | M11: =IF(COUNT(C11:I11)<2,"",IF(L11>$D$3,"Methods disagree","Consistent")) | O11: Reading disagreements
B12: =IF(A12="","",IFERROR(INDEX(DSC!$C$23:$C$42,MATCH(A12,DSC!$A$23:$A$42,0)),IFERROR(INDEX(FTIR!$C$11:$C$35,MATCH(A12,FTIR!$A$11:$A$35,0)),IFERROR(INDEX(DMA!$C$18:$C$37,MATCH(A12,DMA!$A$18:$A$37,0)),IFERROR(INDEX(TMA!$C$20:$C$39,MATCH(A12,TMA!$A$20:$A$39,0)),IFERROR(INDEX(TMA!$C$43:$C$62,MATCH(A12,TMA!$A$43:$A$62,0)),"")))))) | C12: =IF($A12="","",IFERROR(INDEX(DSC!$H$23:$H$42,MATCH($A12,DSC!$A$23:$A$42,0)),"")) | D12: =IF($A12="","",IFERROR(INDEX(DSC!$K$23:$K$42,MATCH($A12,DSC!$A$23:$A$42,0)),"")) | E12: =IF($A12="","",IFERROR(INDEX(FTIR!$H$11:$H$35,MATCH($A12,FTIR!$A$11:$A$35,0)),"")) | F12: =IF($A12="","",IFERROR(INDEX(DMA!$K$18:$K$37,MATCH($A12,DMA!$A$18:$A$37,0)),"")) | G12: =IF($A12="","",IFERROR(INDEX(DMA!$L$18:$L$37,MATCH($A12,DMA!$A$18:$A$37,0)),"")) | H12: =IF($A12="","",IFERROR(INDEX(TMA!$S$20:$S$39,MATCH($A12,TMA!$A$20:$A$39,0)),"")) | I12: =IF($A12="","",IFERROR(INDEX(TMA!$T$43:$T$62,MATCH($A12,TMA!$A$43:$A$62,0)),"")) | J12: =IF(COUNT(C12:I12)=0,"",AVERAGE(C12:I12)) | K12: =IF(COUNT(C12:I12)<2,"",STDEV(C12:I12)) | L12: =IF(COUNT(C12:I12)<2,"",MAX(C12:I12)-MIN(C12:I12)) | M12: =IF(COUNT(C12:I12)<2,"",IF(L12>$D$3,"Methods disagree","Consistent")) | O12: • FTIR > DSC heat → NCO used without urethane heat: moisture → urea, allophanate, isocyanurate.
B13: =IF(A13="","",IFERROR(INDEX(DSC!$C$23:$C$42,MATCH(A13,DSC!$A$23:$A$42,0)),IFERROR(INDEX(FTIR!$C$11:$C$35,MATCH(A13,FTIR!$A$11:$A$35,0)),IFERROR(INDEX(DMA!$C$18:$C$37,MATCH(A13,DMA!$A$18:$A$37,0)),IFERROR(INDEX(TMA!$C$20:$C$39,MATCH(A13,TMA!$A$20:$A$39,0)),IFERROR(INDEX(TMA!$C$43:$C$62,MATCH(A13,TMA!$A$43:$A$62,0)),"")))))) | C13: =IF($A13="","",IFERROR(INDEX(DSC!$H$23:$H$42,MATCH($A13,DSC!$A$23:$A$42,0)),"")) | D13: =IF($A13="","",IFERROR(INDEX(DSC!$K$23:$K$42,MATCH($A13,DSC!$A$23:$A$42,0)),"")) | E13: =IF($A13="","",IFERROR(INDEX(FTIR!$H$11:$H$35,MATCH($A13,FTIR!$A$11:$A$35,0)),"")) | F13: =IF($A13="","",IFERROR(INDEX(DMA!$K$18:$K$37,MATCH($A13,DMA!$A$18:$A$37,0)),"")) | G13: =IF($A13="","",IFERROR(INDEX(DMA!$L$18:$L$37,MATCH($A13,DMA!$A$18:$A$37,0)),"")) | H13: =IF($A13="","",IFERROR(INDEX(TMA!$S$20:$S$39,MATCH($A13,TMA!$A$20:$A$39,0)),"")) | I13: =IF($A13="","",IFERROR(INDEX(TMA!$T$43:$T$62,MATCH($A13,TMA!$A$43:$A$62,0)),"")) | J13: =IF(COUNT(C13:I13)=0,"",AVERAGE(C13:I13)) | K13: =IF(COUNT(C13:I13)<2,"",STDEV(C13:I13)) | L13: =IF(COUNT(C13:I13)<2,"",MAX(C13:I13)-MIN(C13:I13)) | M13: =IF(COUNT(C13:I13)<2,"",IF(L13>$D$3,"Methods disagree","Consistent")) | O13: • Modulus routes (DMA, TMA) > others → physical crosslinks or hard-segment phase separation.
B14: =IF(A14="","",IFERROR(INDEX(DSC!$C$23:$C$42,MATCH(A14,DSC!$A$23:$A$42,0)),IFERROR(INDEX(FTIR!$C$11:$C$35,MATCH(A14,FTIR!$A$11:$A$35,0)),IFERROR(INDEX(DMA!$C$18:$C$37,MATCH(A14,DMA!$A$18:$A$37,0)),IFERROR(INDEX(TMA!$C$20:$C$39,MATCH(A14,TMA!$A$20:$A$39,0)),IFERROR(INDEX(TMA!$C$43:$C$62,MATCH(A14,TMA!$A$43:$A$62,0)),"")))))) | C14: =IF($A14="","",IFERROR(INDEX(DSC!$H$23:$H$42,MATCH($A14,DSC!$A$23:$A$42,0)),"")) | D14: =IF($A14="","",IFERROR(INDEX(DSC!$K$23:$K$42,MATCH($A14,DSC!$A$23:$A$42,0)),"")) | E14: =IF($A14="","",IFERROR(INDEX(FTIR!$H$11:$H$35,MATCH($A14,FTIR!$A$11:$A$35,0)),"")) | F14: =IF($A14="","",IFERROR(INDEX(DMA!$K$18:$K$37,MATCH($A14,DMA!$A$18:$A$37,0)),"")) | G14: =IF($A14="","",IFERROR(INDEX(DMA!$L$18:$L$37,MATCH($A14,DMA!$A$18:$A$37,0)),"")) | H14: =IF($A14="","",IFERROR(INDEX(TMA!$S$20:$S$39,MATCH($A14,TMA!$A$20:$A$39,0)),"")) | I14: =IF($A14="","",IFERROR(INDEX(TMA!$T$43:$T$62,MATCH($A14,TMA!$A$43:$A$62,0)),"")) | J14: =IF(COUNT(C14:I14)=0,"",AVERAGE(C14:I14)) | K14: =IF(COUNT(C14:I14)<2,"",STDEV(C14:I14)) | L14: =IF(COUNT(C14:I14)<2,"",MAX(C14:I14)-MIN(C14:I14)) | M14: =IF(COUNT(C14:I14)<2,"",IF(L14>$D$3,"Methods disagree","Consistent")) | O14: • Tg routes scatter at low α → Tg barely moves early in cure when λ < 1; trust heat or FTIR there.
B15: =IF(A15="","",IFERROR(INDEX(DSC!$C$23:$C$42,MATCH(A15,DSC!$A$23:$A$42,0)),IFERROR(INDEX(FTIR!$C$11:$C$35,MATCH(A15,FTIR!$A$11:$A$35,0)),IFERROR(INDEX(DMA!$C$18:$C$37,MATCH(A15,DMA!$A$18:$A$37,0)),IFERROR(INDEX(TMA!$C$20:$C$39,MATCH(A15,TMA!$A$20:$A$39,0)),IFERROR(INDEX(TMA!$C$43:$C$62,MATCH(A15,TMA!$A$43:$A$62,0)),"")))))) | C15: =IF($A15="","",IFERROR(INDEX(DSC!$H$23:$H$42,MATCH($A15,DSC!$A$23:$A$42,0)),"")) | D15: =IF($A15="","",IFERROR(INDEX(DSC!$K$23:$K$42,MATCH($A15,DSC!$A$23:$A$42,0)),"")) | E15: =IF($A15="","",IFERROR(INDEX(FTIR!$H$11:$H$35,MATCH($A15,FTIR!$A$11:$A$35,0)),"")) | F15: =IF($A15="","",IFERROR(INDEX(DMA!$K$18:$K$37,MATCH($A15,DMA!$A$18:$A$37,0)),"")) | G15: =IF($A15="","",IFERROR(INDEX(DMA!$L$18:$L$37,MATCH($A15,DMA!$A$18:$A$37,0)),"")) | H15: =IF($A15="","",IFERROR(INDEX(TMA!$S$20:$S$39,MATCH($A15,TMA!$A$20:$A$39,0)),"")) | I15: =IF($A15="","",IFERROR(INDEX(TMA!$T$43:$T$62,MATCH($A15,TMA!$A$43:$A$62,0)),"")) | J15: =IF(COUNT(C15:I15)=0,"",AVERAGE(C15:I15)) | K15: =IF(COUNT(C15:I15)<2,"",STDEV(C15:I15)) | L15: =IF(COUNT(C15:I15)<2,"",MAX(C15:I15)-MIN(C15:I15)) | M15: =IF(COUNT(C15:I15)<2,"",IF(L15>$D$3,"Methods disagree","Consistent")) | O15: • DSC heat low at high α → a small residual exotherm lost in noise, or a baseline drawn too high.
B16: =IF(A16="","",IFERROR(INDEX(DSC!$C$23:$C$42,MATCH(A16,DSC!$A$23:$A$42,0)),IFERROR(INDEX(FTIR!$C$11:$C$35,MATCH(A16,FTIR!$A$11:$A$35,0)),IFERROR(INDEX(DMA!$C$18:$C$37,MATCH(A16,DMA!$A$18:$A$37,0)),IFERROR(INDEX(TMA!$C$20:$C$39,MATCH(A16,TMA!$A$20:$A$39,0)),IFERROR(INDEX(TMA!$C$43:$C$62,MATCH(A16,TMA!$A$43:$A$62,0)),"")))))) | C16: =IF($A16="","",IFERROR(INDEX(DSC!$H$23:$H$42,MATCH($A16,DSC!$A$23:$A$42,0)),"")) | D16: =IF($A16="","",IFERROR(INDEX(DSC!$K$23:$K$42,MATCH($A16,DSC!$A$23:$A$42,0)),"")) | E16: =IF($A16="","",IFERROR(INDEX(FTIR!$H$11:$H$35,MATCH($A16,FTIR!$A$11:$A$35,0)),"")) | F16: =IF($A16="","",IFERROR(INDEX(DMA!$K$18:$K$37,MATCH($A16,DMA!$A$18:$A$37,0)),"")) | G16: =IF($A16="","",IFERROR(INDEX(DMA!$L$18:$L$37,MATCH($A16,DMA!$A$18:$A$37,0)),"")) | H16: =IF($A16="","",IFERROR(INDEX(TMA!$S$20:$S$39,MATCH($A16,TMA!$A$20:$A$39,0)),"")) | I16: =IF($A16="","",IFERROR(INDEX(TMA!$T$43:$T$62,MATCH($A16,TMA!$A$43:$A$62,0)),"")) | J16: =IF(COUNT(C16:I16)=0,"",AVERAGE(C16:I16)) | K16: =IF(COUNT(C16:I16)<2,"",STDEV(C16:I16)) | L16: =IF(COUNT(C16:I16)<2,"",MAX(C16:I16)-MIN(C16:I16)) | M16: =IF(COUNT(C16:I16)<2,"",IF(L16>$D$3,"Methods disagree","Consistent")) | O16: Specimens
B17: =IF(A17="","",IFERROR(INDEX(DSC!$C$23:$C$42,MATCH(A17,DSC!$A$23:$A$42,0)),IFERROR(INDEX(FTIR!$C$11:$C$35,MATCH(A17,FTIR!$A$11:$A$35,0)),IFERROR(INDEX(DMA!$C$18:$C$37,MATCH(A17,DMA!$A$18:$A$37,0)),IFERROR(INDEX(TMA!$C$20:$C$39,MATCH(A17,TMA!$A$20:$A$39,0)),IFERROR(INDEX(TMA!$C$43:$C$62,MATCH(A17,TMA!$A$43:$A$62,0)),"")))))) | C17: =IF($A17="","",IFERROR(INDEX(DSC!$H$23:$H$42,MATCH($A17,DSC!$A$23:$A$42,0)),"")) | D17: =IF($A17="","",IFERROR(INDEX(DSC!$K$23:$K$42,MATCH($A17,DSC!$A$23:$A$42,0)),"")) | E17: =IF($A17="","",IFERROR(INDEX(FTIR!$H$11:$H$35,MATCH($A17,FTIR!$A$11:$A$35,0)),"")) | F17: =IF($A17="","",IFERROR(INDEX(DMA!$K$18:$K$37,MATCH($A17,DMA!$A$18:$A$37,0)),"")) | G17: =IF($A17="","",IFERROR(INDEX(DMA!$L$18:$L$37,MATCH($A17,DMA!$A$18:$A$37,0)),"")) | H17: =IF($A17="","",IFERROR(INDEX(TMA!$S$20:$S$39,MATCH($A17,TMA!$A$20:$A$39,0)),"")) | I17: =IF($A17="","",IFERROR(INDEX(TMA!$T$43:$T$62,MATCH($A17,TMA!$A$43:$A$62,0)),"")) | J17: =IF(COUNT(C17:I17)=0,"",AVERAGE(C17:I17)) | K17: =IF(COUNT(C17:I17)<2,"",STDEV(C17:I17)) | L17: =IF(COUNT(C17:I17)<2,"",MAX(C17:I17)-MIN(C17:I17)) | M17: =IF(COUNT(C17:I17)<2,"",IF(L17>$D$3,"Methods disagree","Consistent")) | O17: Matched specimens: one batch, cured together, the same Sample ID on every sheet.
B18: =IF(A18="","",IFERROR(INDEX(DSC!$C$23:$C$42,MATCH(A18,DSC!$A$23:$A$42,0)),IFERROR(INDEX(FTIR!$C$11:$C$35,MATCH(A18,FTIR!$A$11:$A$35,0)),IFERROR(INDEX(DMA!$C$18:$C$37,MATCH(A18,DMA!$A$18:$A$37,0)),IFERROR(INDEX(TMA!$C$20:$C$39,MATCH(A18,TMA!$A$20:$A$39,0)),IFERROR(INDEX(TMA!$C$43:$C$62,MATCH(A18,TMA!$A$43:$A$62,0)),"")))))) | C18: =IF($A18="","",IFERROR(INDEX(DSC!$H$23:$H$42,MATCH($A18,DSC!$A$23:$A$42,0)),"")) | D18: =IF($A18="","",IFERROR(INDEX(DSC!$K$23:$K$42,MATCH($A18,DSC!$A$23:$A$42,0)),"")) | E18: =IF($A18="","",IFERROR(INDEX(FTIR!$H$11:$H$35,MATCH($A18,FTIR!$A$11:$A$35,0)),"")) | F18: =IF($A18="","",IFERROR(INDEX(DMA!$K$18:$K$37,MATCH($A18,DMA!$A$18:$A$37,0)),"")) | G18: =IF($A18="","",IFERROR(INDEX(DMA!$L$18:$L$37,MATCH($A18,DMA!$A$18:$A$37,0)),"")) | H18: =IF($A18="","",IFERROR(INDEX(TMA!$S$20:$S$39,MATCH($A18,TMA!$A$20:$A$39,0)),"")) | I18: =IF($A18="","",IFERROR(INDEX(TMA!$T$43:$T$62,MATCH($A18,TMA!$A$43:$A$62,0)),"")) | J18: =IF(COUNT(C18:I18)=0,"",AVERAGE(C18:I18)) | K18: =IF(COUNT(C18:I18)<2,"",STDEV(C18:I18)) | L18: =IF(COUNT(C18:I18)<2,"",MAX(C18:I18)-MIN(C18:I18)) | M18: =IF(COUNT(C18:I18)<2,"",IF(L18>$D$3,"Methods disagree","Consistent")) | O18: ▸ Full preparation protocol for this sheet (Sample_Prep)
B19: =IF(A19="","",IFERROR(INDEX(DSC!$C$23:$C$42,MATCH(A19,DSC!$A$23:$A$42,0)),IFERROR(INDEX(FTIR!$C$11:$C$35,MATCH(A19,FTIR!$A$11:$A$35,0)),IFERROR(INDEX(DMA!$C$18:$C$37,MATCH(A19,DMA!$A$18:$A$37,0)),IFERROR(INDEX(TMA!$C$20:$C$39,MATCH(A19,TMA!$A$20:$A$39,0)),IFERROR(INDEX(TMA!$C$43:$C$62,MATCH(A19,TMA!$A$43:$A$62,0)),"")))))) | C19: =IF($A19="","",IFERROR(INDEX(DSC!$H$23:$H$42,MATCH($A19,DSC!$A$23:$A$42,0)),"")) | D19: =IF($A19="","",IFERROR(INDEX(DSC!$K$23:$K$42,MATCH($A19,DSC!$A$23:$A$42,0)),"")) | E19: =IF($A19="","",IFERROR(INDEX(FTIR!$H$11:$H$35,MATCH($A19,FTIR!$A$11:$A$35,0)),"")) | F19: =IF($A19="","",IFERROR(INDEX(DMA!$K$18:$K$37,MATCH($A19,DMA!$A$18:$A$37,0)),"")) | G19: =IF($A19="","",IFERROR(INDEX(DMA!$L$18:$L$37,MATCH($A19,DMA!$A$18:$A$37,0)),"")) | H19: =IF($A19="","",IFERROR(INDEX(TMA!$S$20:$S$39,MATCH($A19,TMA!$A$20:$A$39,0)),"")) | I19: =IF($A19="","",IFERROR(INDEX(TMA!$T$43:$T$62,MATCH($A19,TMA!$A$43:$A$62,0)),"")) | J19: =IF(COUNT(C19:I19)=0,"",AVERAGE(C19:I19)) | K19: =IF(COUNT(C19:I19)<2,"",STDEV(C19:I19)) | L19: =IF(COUNT(C19:I19)<2,"",MAX(C19:I19)-MIN(C19:I19)) | M19: =IF(COUNT(C19:I19)<2,"",IF(L19>$D$3,"Methods disagree","Consistent"))
B20: =IF(A20="","",IFERROR(INDEX(DSC!$C$23:$C$42,MATCH(A20,DSC!$A$23:$A$42,0)),IFERROR(INDEX(FTIR!$C$11:$C$35,MATCH(A20,FTIR!$A$11:$A$35,0)),IFERROR(INDEX(DMA!$C$18:$C$37,MATCH(A20,DMA!$A$18:$A$37,0)),IFERROR(INDEX(TMA!$C$20:$C$39,MATCH(A20,TMA!$A$20:$A$39,0)),IFERROR(INDEX(TMA!$C$43:$C$62,MATCH(A20,TMA!$A$43:$A$62,0)),"")))))) | C20: =IF($A20="","",IFERROR(INDEX(DSC!$H$23:$H$42,MATCH($A20,DSC!$A$23:$A$42,0)),"")) | D20: =IF($A20="","",IFERROR(INDEX(DSC!$K$23:$K$42,MATCH($A20,DSC!$A$23:$A$42,0)),"")) | E20: =IF($A20="","",IFERROR(INDEX(FTIR!$H$11:$H$35,MATCH($A20,FTIR!$A$11:$A$35,0)),"")) | F20: =IF($A20="","",IFERROR(INDEX(DMA!$K$18:$K$37,MATCH($A20,DMA!$A$18:$A$37,0)),"")) | G20: =IF($A20="","",IFERROR(INDEX(DMA!$L$18:$L$37,MATCH($A20,DMA!$A$18:$A$37,0)),"")) | H20: =IF($A20="","",IFERROR(INDEX(TMA!$S$20:$S$39,MATCH($A20,TMA!$A$20:$A$39,0)),"")) | I20: =IF($A20="","",IFERROR(INDEX(TMA!$T$43:$T$62,MATCH($A20,TMA!$A$43:$A$62,0)),"")) | J20: =IF(COUNT(C20:I20)=0,"",AVERAGE(C20:I20)) | K20: =IF(COUNT(C20:I20)<2,"",STDEV(C20:I20)) | L20: =IF(COUNT(C20:I20)<2,"",MAX(C20:I20)-MIN(C20:I20)) | M20: =IF(COUNT(C20:I20)<2,"",IF(L20>$D$3,"Methods disagree","Consistent")) | O20: Figure — schematic only: the usual patterns when methods disagree.
B21: =IF(A21="","",IFERROR(INDEX(DSC!$C$23:$C$42,MATCH(A21,DSC!$A$23:$A$42,0)),IFERROR(INDEX(FTIR!$C$11:$C$35,MATCH(A21,FTIR!$A$11:$A$35,0)),IFERROR(INDEX(DMA!$C$18:$C$37,MATCH(A21,DMA!$A$18:$A$37,0)),IFERROR(INDEX(TMA!$C$20:$C$39,MATCH(A21,TMA!$A$20:$A$39,0)),IFERROR(INDEX(TMA!$C$43:$C$62,MATCH(A21,TMA!$A$43:$A$62,0)),"")))))) | C21: =IF($A21="","",IFERROR(INDEX(DSC!$H$23:$H$42,MATCH($A21,DSC!$A$23:$A$42,0)),"")) | D21: =IF($A21="","",IFERROR(INDEX(DSC!$K$23:$K$42,MATCH($A21,DSC!$A$23:$A$42,0)),"")) | E21: =IF($A21="","",IFERROR(INDEX(FTIR!$H$11:$H$35,MATCH($A21,FTIR!$A$11:$A$35,0)),"")) | F21: =IF($A21="","",IFERROR(INDEX(DMA!$K$18:$K$37,MATCH($A21,DMA!$A$18:$A$37,0)),"")) | G21: =IF($A21="","",IFERROR(INDEX(DMA!$L$18:$L$37,MATCH($A21,DMA!$A$18:$A$37,0)),"")) | H21: =IF($A21="","",IFERROR(INDEX(TMA!$S$20:$S$39,MATCH($A21,TMA!$A$20:$A$39,0)),"")) | I21: =IF($A21="","",IFERROR(INDEX(TMA!$T$43:$T$62,MATCH($A21,TMA!$A$43:$A$62,0)),"")) | J21: =IF(COUNT(C21:I21)=0,"",AVERAGE(C21:I21)) | K21: =IF(COUNT(C21:I21)<2,"",STDEV(C21:I21)) | L21: =IF(COUNT(C21:I21)<2,"",MAX(C21:I21)-MIN(C21:I21)) | M21: =IF(COUNT(C21:I21)<2,"",IF(L21>$D$3,"Methods disagree","Consistent"))
B22: =IF(A22="","",IFERROR(INDEX(DSC!$C$23:$C$42,MATCH(A22,DSC!$A$23:$A$42,0)),IFERROR(INDEX(FTIR!$C$11:$C$35,MATCH(A22,FTIR!$A$11:$A$35,0)),IFERROR(INDEX(DMA!$C$18:$C$37,MATCH(A22,DMA!$A$18:$A$37,0)),IFERROR(INDEX(TMA!$C$20:$C$39,MATCH(A22,TMA!$A$20:$A$39,0)),IFERROR(INDEX(TMA!$C$43:$C$62,MATCH(A22,TMA!$A$43:$A$62,0)),"")))))) | C22: =IF($A22="","",IFERROR(INDEX(DSC!$H$23:$H$42,MATCH($A22,DSC!$A$23:$A$42,0)),"")) | D22: =IF($A22="","",IFERROR(INDEX(DSC!$K$23:$K$42,MATCH($A22,DSC!$A$23:$A$42,0)),"")) | E22: =IF($A22="","",IFERROR(INDEX(FTIR!$H$11:$H$35,MATCH($A22,FTIR!$A$11:$A$35,0)),"")) | F22: =IF($A22="","",IFERROR(INDEX(DMA!$K$18:$K$37,MATCH($A22,DMA!$A$18:$A$37,0)),"")) | G22: =IF($A22="","",IFERROR(INDEX(DMA!$L$18:$L$37,MATCH($A22,DMA!$A$18:$A$37,0)),"")) | H22: =IF($A22="","",IFERROR(INDEX(TMA!$S$20:$S$39,MATCH($A22,TMA!$A$20:$A$39,0)),"")) | I22: =IF($A22="","",IFERROR(INDEX(TMA!$T$43:$T$62,MATCH($A22,TMA!$A$43:$A$62,0)),"")) | J22: =IF(COUNT(C22:I22)=0,"",AVERAGE(C22:I22)) | K22: =IF(COUNT(C22:I22)<2,"",STDEV(C22:I22)) | L22: =IF(COUNT(C22:I22)<2,"",MAX(C22:I22)-MIN(C22:I22)) | M22: =IF(COUNT(C22:I22)<2,"",IF(L22>$D$3,"Methods disagree","Consistent"))
B23: =IF(A23="","",IFERROR(INDEX(DSC!$C$23:$C$42,MATCH(A23,DSC!$A$23:$A$42,0)),IFERROR(INDEX(FTIR!$C$11:$C$35,MATCH(A23,FTIR!$A$11:$A$35,0)),IFERROR(INDEX(DMA!$C$18:$C$37,MATCH(A23,DMA!$A$18:$A$37,0)),IFERROR(INDEX(TMA!$C$20:$C$39,MATCH(A23,TMA!$A$20:$A$39,0)),IFERROR(INDEX(TMA!$C$43:$C$62,MATCH(A23,TMA!$A$43:$A$62,0)),"")))))) | C23: =IF($A23="","",IFERROR(INDEX(DSC!$H$23:$H$42,MATCH($A23,DSC!$A$23:$A$42,0)),"")) | D23: =IF($A23="","",IFERROR(INDEX(DSC!$K$23:$K$42,MATCH($A23,DSC!$A$23:$A$42,0)),"")) | E23: =IF($A23="","",IFERROR(INDEX(FTIR!$H$11:$H$35,MATCH($A23,FTIR!$A$11:$A$35,0)),"")) | F23: =IF($A23="","",IFERROR(INDEX(DMA!$K$18:$K$37,MATCH($A23,DMA!$A$18:$A$37,0)),"")) | G23: =IF($A23="","",IFERROR(INDEX(DMA!$L$18:$L$37,MATCH($A23,DMA!$A$18:$A$37,0)),"")) | H23: =IF($A23="","",IFERROR(INDEX(TMA!$S$20:$S$39,MATCH($A23,TMA!$A$20:$A$39,0)),"")) | I23: =IF($A23="","",IFERROR(INDEX(TMA!$T$43:$T$62,MATCH($A23,TMA!$A$43:$A$62,0)),"")) | J23: =IF(COUNT(C23:I23)=0,"",AVERAGE(C23:I23)) | K23: =IF(COUNT(C23:I23)<2,"",STDEV(C23:I23)) | L23: =IF(COUNT(C23:I23)<2,"",MAX(C23:I23)-MIN(C23:I23)) | M23: =IF(COUNT(C23:I23)<2,"",IF(L23>$D$3,"Methods disagree","Consistent"))
B24: =IF(A24="","",IFERROR(INDEX(DSC!$C$23:$C$42,MATCH(A24,DSC!$A$23:$A$42,0)),IFERROR(INDEX(FTIR!$C$11:$C$35,MATCH(A24,FTIR!$A$11:$A$35,0)),IFERROR(INDEX(DMA!$C$18:$C$37,MATCH(A24,DMA!$A$18:$A$37,0)),IFERROR(INDEX(TMA!$C$20:$C$39,MATCH(A24,TMA!$A$20:$A$39,0)),IFERROR(INDEX(TMA!$C$43:$C$62,MATCH(A24,TMA!$A$43:$A$62,0)),"")))))) | C24: =IF($A24="","",IFERROR(INDEX(DSC!$H$23:$H$42,MATCH($A24,DSC!$A$23:$A$42,0)),"")) | D24: =IF($A24="","",IFERROR(INDEX(DSC!$K$23:$K$42,MATCH($A24,DSC!$A$23:$A$42,0)),"")) | E24: =IF($A24="","",IFERROR(INDEX(FTIR!$H$11:$H$35,MATCH($A24,FTIR!$A$11:$A$35,0)),"")) | F24: =IF($A24="","",IFERROR(INDEX(DMA!$K$18:$K$37,MATCH($A24,DMA!$A$18:$A$37,0)),"")) | G24: =IF($A24="","",IFERROR(INDEX(DMA!$L$18:$L$37,MATCH($A24,DMA!$A$18:$A$37,0)),"")) | H24: =IF($A24="","",IFERROR(INDEX(TMA!$S$20:$S$39,MATCH($A24,TMA!$A$20:$A$39,0)),"")) | I24: =IF($A24="","",IFERROR(INDEX(TMA!$T$43:$T$62,MATCH($A24,TMA!$A$43:$A$62,0)),"")) | J24: =IF(COUNT(C24:I24)=0,"",AVERAGE(C24:I24)) | K24: =IF(COUNT(C24:I24)<2,"",STDEV(C24:I24)) | L24: =IF(COUNT(C24:I24)<2,"",MAX(C24:I24)-MIN(C24:I24)) | M24: =IF(COUNT(C24:I24)<2,"",IF(L24>$D$3,"Methods disagree","Consistent"))
B25: =IF(A25="","",IFERROR(INDEX(DSC!$C$23:$C$42,MATCH(A25,DSC!$A$23:$A$42,0)),IFERROR(INDEX(FTIR!$C$11:$C$35,MATCH(A25,FTIR!$A$11:$A$35,0)),IFERROR(INDEX(DMA!$C$18:$C$37,MATCH(A25,DMA!$A$18:$A$37,0)),IFERROR(INDEX(TMA!$C$20:$C$39,MATCH(A25,TMA!$A$20:$A$39,0)),IFERROR(INDEX(TMA!$C$43:$C$62,MATCH(A25,TMA!$A$43:$A$62,0)),"")))))) | C25: =IF($A25="","",IFERROR(INDEX(DSC!$H$23:$H$42,MATCH($A25,DSC!$A$23:$A$42,0)),"")) | D25: =IF($A25="","",IFERROR(INDEX(DSC!$K$23:$K$42,MATCH($A25,DSC!$A$23:$A$42,0)),"")) | E25: =IF($A25="","",IFERROR(INDEX(FTIR!$H$11:$H$35,MATCH($A25,FTIR!$A$11:$A$35,0)),"")) | F25: =IF($A25="","",IFERROR(INDEX(DMA!$K$18:$K$37,MATCH($A25,DMA!$A$18:$A$37,0)),"")) | G25: =IF($A25="","",IFERROR(INDEX(DMA!$L$18:$L$37,MATCH($A25,DMA!$A$18:$A$37,0)),"")) | H25: =IF($A25="","",IFERROR(INDEX(TMA!$S$20:$S$39,MATCH($A25,TMA!$A$20:$A$39,0)),"")) | I25: =IF($A25="","",IFERROR(INDEX(TMA!$T$43:$T$62,MATCH($A25,TMA!$A$43:$A$62,0)),"")) | J25: =IF(COUNT(C25:I25)=0,"",AVERAGE(C25:I25)) | K25: =IF(COUNT(C25:I25)<2,"",STDEV(C25:I25)) | L25: =IF(COUNT(C25:I25)<2,"",MAX(C25:I25)-MIN(C25:I25)) | M25: =IF(COUNT(C25:I25)<2,"",IF(L25>$D$3,"Methods disagree","Consistent"))
A27: Blank = no data for that sample on that sheet (e.g. pre-gel samples have no DMA or TMA value). Text results such as "> theoretical" are excluded from the statistics.
A28: Typical pattern: FTIR ≥ DSC heat when side reactions consume NCO; the modulus routes (DMA, TMA) read high in phase-separated (segmented) PUs.

Sheet Formulation
A1: Formulation & Network Parameters | F1: HOW TO USE — Formulation
A2: Inputs here feed DSC (reactive fraction), FTIR (%NCO, OH conversion) and DMA (Miller–Macosko network model). ▸ How to use this sheet: column F | F2: ↩ Back to the Guide
A3: Parameter | B3: Value | C3: Units | D3: Note | F3: Steps
A4: Polyol mass | B4: 10 | C4: g | D4: Example: PPG triol, MW ≈ 3000 | F4: 1 Polyol (B4–B6): mass, equivalent weight per OH, functionality.
A5: Polyol equivalent weight (per OH) | B5: 1000 | C5: g/eq | D5: EW = 56100 / OH number (mg KOH/g) | F5: EW = 56100 / OH number (mg KOH/g). Take it from the CoA of the lot you actually used.
A6: Polyol functionality | B6: 3 | C6: – | D6: Integer; 2 for a diol | F6: 2 Isocyanate (B7–B9): mass, equivalent weight per NCO, functionality.
A7: Isocyanate mass | B7: 1.111 | C7: g | D7: Example: IPDI | F7: EW = 4202 / %NCO. IPDI 111.1 · HDI 84.1 · MDI 125.1 · TDI 87.1 g/eq.
A8: Isocyanate equivalent weight (per NCO) | B8: 111.1 | C8: g/eq | D8: EW = 4202 / %NCO. IPDI 111.1, HDI 84.1, MDI 125.1, TDI 87.1 | F8: 3 Non-reactive mass (plasticiser, filler, additives) and cured density (B10–B11).
A9: Isocyanate functionality | B9: 2 | C9: – | D9: Integer; 2 for a diisocyanate | F9: 4 Urethane ΔH (B12): keep 90 kJ/mol, or paste DSC!E13 once you have a fresh-mix reference scan.
A10: Non-reactive mass (plasticiser, filler, additives) | B10: 0 | C10: g | D10: Dilutes ΔH per gram of sample; corrected for on the DSC sheet | F10: 5 Check the results: index (B18), initial %NCO (B21), gel point (B27), theoretical ΔH (B31).
A11: Cured density | B11: 1.02 | C11: g/cm³ | D11: Of the whole formulation | F11: 6 B32 must read OK for the DMA and TMA modulus routes; otherwise rely on DSC, FTIR or the Tg routes.
A12: Urethane reaction enthalpy (magnitude) | B12: 90 | C12: kJ/mol NCO | D12: Sanity check only — see Guide. Replace with a value for your chemistry | F12: Every other sheet reads this one — keep one copy of the workbook per formulation.
F13: Specimens
A14: Calculated | F14: Titrate the OH number and %NCO of the actual lots, dry the polyol, and weigh on an analytical balance.
A15: OH equivalents | B15: =B4/B5 | C15: eq | F15: ▸ Full preparation protocol for this sheet (Sample_Prep)
A16: NCO equivalents | B16: =B7/B8 | C16: eq
A17: NCO:OH ratio, r | B17: =B16/B15 | C17: – | F17: Figure — where a network can form. Find your r on the x-axis; DMA and TMA need conversions above the gel curve.
A18: Isocyanate index | B18: =100*B17 | C18: –
A19: Total mass | B19: =B4+B7+B10 | C19: g
A20: Reactive mass fraction, w_r | B20: =(B4+B7)/B19 | C20: – | D20: Used on the DSC sheet
A21: Initial NCO content | B21: =B16*42.02/B19 | C21: wt fraction | D21: NCO = 42.02 g/mol
A22: Specimen volume | B22: =B19/B11*1E-6 | C22: m³
A23: Crosslinker functionality, f | B23: =MAX(B6,B9) | C23: –
A24: Crosslinker component | B24: =IF(B23<=2,"none (linear)",IF(B6>=B9,"Polyol","Isocyanate"))
A25: Crosslinker concentration, [Bf]0 | B25: =IF(B23<=2,0,IF(B6>=B9,B15/B6,B16/B9)/B22) | C25: mol/m³
A26: Maximum attainable NCO conversion | B26: =MIN(1,1/B17) | C26: – | D26: NCO in excess (r > 1) cannot fully react
A27: Gel-point NCO conversion, α_gel | B27: =IF(B23<=2,"no gel (linear)",IF(1/SQRT(B17*(B23-1))>B26,"no gel",1/SQRT(B17*(B23-1)))) | C27: – | D27: Flory–Stockmayer [r(f−1)]^−½
A28: k at maximum conversion (= r·α_max²) | B28: =B17*B26^2 | C28: –
A29: P(F_out) b at maximum conversion | B29: =IF(B23=3,IF(B28<=0.5,1,(1-B28)/B28),IF(B23=4,IF(B28<=1/3,1,(-B28+SQRT(4*B28-3*B28^2))/(2*B28)),1)) | C29: –
A30: Theoretical ν_e at maximum conversion | B30: =B25*IF(B23=3,1.5*(1-B29)^3,IF(B23=4,2*(1-B29)^4+6*B29*(1-B29)^3,0)) | C30: mol/m³ | D30: Miller–Macosko, elastically active strands
A31: Theoretical ΔH_total | B31: =B16*B12*1000/B19 | C31: J/g sample | D31: Compare with measured on DSC sheet
A32: Network-model check | B32: =IF(AND(MIN(B6,B9)=2,OR(B23=3,B23=4)),"OK — A2 + B"&B23&" Miller–Macosko model applies","WARNING — DMA/TMA modulus→α needs one difunctional component and a crosslinker with f = 3 or 4")

Sheet DSC
A1: DSC — residual exotherm and Tg | O1: HOW TO USE — DSC (residual heat)
A2: α = 1 − ΔH_res/ΔH_total on a reactive-resin basis; optional Tg route via DiBenedetto. ▸ How to use this sheet: column O | O2: ↩ Back to the Guide
A3: Reference: uncured, freshly mixed, full dynamic scan
A4: Replicate | B4: Sample mass (mg) | C4: ΔH_total (J/g sample) | D4: w_r | E4: ΔH_total (J/g reactive) | O4: Reference scan — rows 5–7 (skip if you will use the theoretical basis)
A5: Ref-1 | B5: 8.12 | C5: 79.4 | D5: =Formulation!$B$20 | E5: =IF(C5="","",C5/D5) | O5: 1 Mix fresh, load at once, cool below Tg0, then heat at 10 K/min through the whole exotherm.
A6: Ref-2 | B6: 7.95 | C6: 80.6 | D6: =Formulation!$B$20 | E6: =IF(C6="","",C6/D6) | O6: 2 Integrate the exotherm against a linear baseline; enter ΔH in J/g of sample (C5–C7).
D7: =Formulation!$B$20 | E7: =IF(C7="","",C7/D7) | O7: 3 E12 should be close to 100 %. Much lower: heat lost before the scan, or Formulation!B12 too high.
A8: Mean ΔH_total (J/g reactive) | E8: =IF(COUNT(E5:E7)=0,"",AVERAGE(E5:E7)) | O8: Choose the ΔH_total basis — E14
A9: Std. dev. | E9: =IF(COUNT(E5:E7)>1,STDEV(E5:E7),"") | O9: 4 Measured reference = rows 5–7. Theoretical (formulation) = no reference scan needed.
A10: RSD | E10: =IF(COUNT(E5:E7)>1,E9/E8,"") | O10: Partially cured samples — rows 23–42
A11: Theoretical ΔH (J/g reactive) | E11: =Formulation!B31/Formulation!B20 | O11: 5 Scan each sample at the same rate, integrate the same way, and enter ΔH_res in column E.
A12: Measured / theoretical | E12: =IF(E8="","",E8/E11) | F12: Low ratio → reaction before/while loading, or ΔH_urethane input too high | O12: 6 Conversion appears in column H.
A13: Urethane ΔH implied by reference (kJ/mol NCO) | E13: =IF(E8="","",E8*Formulation!B20*Formulation!B19/Formulation!B16/1000) | F13: Copy into Formulation!B12 to calibrate the theoretical basis (valid only if the reference scan reached full cure) | O13: Optional Tg route
A14: ΔH_total basis used for α ▼ | E14: Measured reference | H14: Theoretical = no uncured reference scan needed; accuracy then rests on Formulation!B12 | O14: 7 Enter the Tg midpoint in column I, then Tg0 and Tg∞ (B18–B19). Pick where λ comes from in G17:
A15: ΔH_total used (J/g reactive) | E15: =IF(E14="Theoretical (formulation)",E11,E8) | O15: Fitted (default) = least-squares fit to the residual-heat α of samples that have both (needs ≥ 2);
O16: ΔCp ratio = enter the Tg-step ΔCp of uncured and fully cured material in G18–H18;
A17: DiBenedetto parameters (DSC midpoint Tg) | E17: λ source ▼ | G17: Fitted to residual-heat α | O17: Tg0/Tg∞ estimate = first guess in kelvin; Manual = type λ in J21. B20 shows the λ in use.
A18: Tg0 — uncured (°C) | B18: -65 | C18: °C | E18: ΔCp0 | ΔCp∞ (J/g·K) | G18: 0.5 | H18: 0.23 | I18: → λ | J18: =IF(OR(G18="",H18="",G18=0),"",H18/G18) | O18: 8 Column K = α from Tg; column L = its gap to the heat result.
A19: Tg∞ — fully cured (°C) | B19: -40 | C19: °C | E19: Tg0 / Tg∞ in kelvin | J19: =(B18+273.15)/(B19+273.15) | O19: Specimens
A20: λ used (source picked in G17) | B20: =IF($G$17="ΔCp ratio",J18,IF($G$17="Tg0/Tg∞ estimate",J19,IF($G$17="Manual",J21,J20))) | C20: – | E20: Fitted to residual-heat α | G20: points used | H20: =Lambda_Fit!$AC$5 | J20: =Lambda_Fit!$AC$6 | O20: 5–10 mg in hermetic pans; best: seal pans of fresh mix at t = 0 and cure them in the oven with everything else.
A21: Tg∞: post-cure a sample until Tg stops rising | E21: Manual λ | J21: 0.45 | O21: ▸ Full preparation protocol for this sheet (Sample_Prep)
A22: Sample ID | B22: Cure temp (°C) | C22: Cure time (h) | D22: Sample mass (mg) | E22: ΔH_residual (J/g sample) | F22: w_r | G22: ΔH_residual (J/g reactive) | H22: α — residual heat | I22: Tg midpoint (°C) | J22: x = (Tg−Tg0)/(Tg∞−Tg0) | K22: α — DiBenedetto | L22: α(Tg) − α(heat) | M22: Notes
A23: S0 | B23: 60 | C23: 0 | D23: 8.05 | E23: 80 | F23: =Formulation!$B$20 | G23: =IF(E23="","",E23/F23) | H23: =IF(OR(G23="",$E$15=""),"",1-G23/$E$15) | I23: -65 | J23: =IF(I23="","",(I23-$B$18)/($B$19-$B$18)) | K23: =IF(OR(J23="",$B$20=""),"",J23/($B$20+J23*(1-$B$20))) | L23: =IF(OR(H23="",K23=""),"",K23-H23) | O23: Figure — left: what to integrate on each scan. Right: how λ shapes the Tg–conversion curve.
A24: S1 | B24: 60 | C24: 2 | D24: 7.88 | E24: 44 | F24: =Formulation!$B$20 | G24: =IF(E24="","",E24/F24) | H24: =IF(OR(G24="",$E$15=""),"",1-G24/$E$15) | I24: -58.3 | J24: =IF(I24="","",(I24-$B$18)/($B$19-$B$18)) | K24: =IF(OR(J24="",$B$20=""),"",J24/($B$20+J24*(1-$B$20))) | L24: =IF(OR(H24="",K24=""),"",K24-H24)
A25: S2 | B25: 60 | C25: 8 | D25: 8.21 | E25: 20 | F25: =Formulation!$B$20 | G25: =IF(E25="","",E25/F25) | H25: =IF(OR(G25="",$E$15=""),"",1-G25/$E$15) | I25: -50.6 | J25: =IF(I25="","",(I25-$B$18)/($B$19-$B$18)) | K25: =IF(OR(J25="",$B$20=""),"",J25/($B$20+J25*(1-$B$20))) | L25: =IF(OR(H25="",K25=""),"",K25-H25)
A26: S3 | B26: 60 | C26: 24 | D26: 7.92 | E26: 8 | F26: =Formulation!$B$20 | G26: =IF(E26="","",E26/F26) | H26: =IF(OR(G26="",$E$15=""),"",1-G26/$E$15) | I26: -45 | J26: =IF(I26="","",(I26-$B$18)/($B$19-$B$18)) | K26: =IF(OR(J26="",$B$20=""),"",J26/($B$20+J26*(1-$B$20))) | L26: =IF(OR(H26="",K26=""),"",K26-H26)
A27: S4 | B27: 60 | C27: 72 | D27: 8.1 | E27: 2.4 | F27: =Formulation!$B$20 | G27: =IF(E27="","",E27/F27) | H27: =IF(OR(G27="",$E$15=""),"",1-G27/$E$15) | I27: -41.6 | J27: =IF(I27="","",(I27-$B$18)/($B$19-$B$18)) | K27: =IF(OR(J27="",$B$20=""),"",J27/($B$20+J27*(1-$B$20))) | L27: =IF(OR(H27="",K27=""),"",K27-H27)
F28: =Formulation!$B$20 | G28: =IF(E28="","",E28/F28) | H28: =IF(OR(G28="",$E$15=""),"",1-G28/$E$15) | J28: =IF(I28="","",(I28-$B$18)/($B$19-$B$18)) | K28: =IF(OR(J28="",$B$20=""),"",J28/($B$20+J28*(1-$B$20))) | L28: =IF(OR(H28="",K28=""),"",K28-H28)
F29: =Formulation!$B$20 | G29: =IF(E29="","",E29/F29) | H29: =IF(OR(G29="",$E$15=""),"",1-G29/$E$15) | J29: =IF(I29="","",(I29-$B$18)/($B$19-$B$18)) | K29: =IF(OR(J29="",$B$20=""),"",J29/($B$20+J29*(1-$B$20))) | L29: =IF(OR(H29="",K29=""),"",K29-H29)
F30: =Formulation!$B$20 | G30: =IF(E30="","",E30/F30) | H30: =IF(OR(G30="",$E$15=""),"",1-G30/$E$15) | J30: =IF(I30="","",(I30-$B$18)/($B$19-$B$18)) | K30: =IF(OR(J30="",$B$20=""),"",J30/($B$20+J30*(1-$B$20))) | L30: =IF(OR(H30="",K30=""),"",K30-H30)
F31: =Formulation!$B$20 | G31: =IF(E31="","",E31/F31) | H31: =IF(OR(G31="",$E$15=""),"",1-G31/$E$15) | J31: =IF(I31="","",(I31-$B$18)/($B$19-$B$18)) | K31: =IF(OR(J31="",$B$20=""),"",J31/($B$20+J31*(1-$B$20))) | L31: =IF(OR(H31="",K31=""),"",K31-H31)
F32: =Formulation!$B$20 | G32: =IF(E32="","",E32/F32) | H32: =IF(OR(G32="",$E$15=""),"",1-G32/$E$15) | J32: =IF(I32="","",(I32-$B$18)/($B$19-$B$18)) | K32: =IF(OR(J32="",$B$20=""),"",J32/($B$20+J32*(1-$B$20))) | L32: =IF(OR(H32="",K32=""),"",K32-H32)
F33: =Formulation!$B$20 | G33: =IF(E33="","",E33/F33) | H33: =IF(OR(G33="",$E$15=""),"",1-G33/$E$15) | J33: =IF(I33="","",(I33-$B$18)/($B$19-$B$18)) | K33: =IF(OR(J33="",$B$20=""),"",J33/($B$20+J33*(1-$B$20))) | L33: =IF(OR(H33="",K33=""),"",K33-H33)
F34: =Formulation!$B$20 | G34: =IF(E34="","",E34/F34) | H34: =IF(OR(G34="",$E$15=""),"",1-G34/$E$15) | J34: =IF(I34="","",(I34-$B$18)/($B$19-$B$18)) | K34: =IF(OR(J34="",$B$20=""),"",J34/($B$20+J34*(1-$B$20))) | L34: =IF(OR(H34="",K34=""),"",K34-H34)
F35: =Formulation!$B$20 | G35: =IF(E35="","",E35/F35) | H35: =IF(OR(G35="",$E$15=""),"",1-G35/$E$15) | J35: =IF(I35="","",(I35-$B$18)/($B$19-$B$18)) | K35: =IF(OR(J35="",$B$20=""),"",J35/($B$20+J35*(1-$B$20))) | L35: =IF(OR(H35="",K35=""),"",K35-H35)
F36: =Formulation!$B$20 | G36: =IF(E36="","",E36/F36) | H36: =IF(OR(G36="",$E$15=""),"",1-G36/$E$15) | J36: =IF(I36="","",(I36-$B$18)/($B$19-$B$18)) | K36: =IF(OR(J36="",$B$20=""),"",J36/($B$20+J36*(1-$B$20))) | L36: =IF(OR(H36="",K36=""),"",K36-H36)
F37: =Formulation!$B$20 | G37: =IF(E37="","",E37/F37) | H37: =IF(OR(G37="",$E$15=""),"",1-G37/$E$15) | J37: =IF(I37="","",(I37-$B$18)/($B$19-$B$18)) | K37: =IF(OR(J37="",$B$20=""),"",J37/($B$20+J37*(1-$B$20))) | L37: =IF(OR(H37="",K37=""),"",K37-H37)
F38: =Formulation!$B$20 | G38: =IF(E38="","",E38/F38) | H38: =IF(OR(G38="",$E$15=""),"",1-G38/$E$15) | J38: =IF(I38="","",(I38-$B$18)/($B$19-$B$18)) | K38: =IF(OR(J38="",$B$20=""),"",J38/($B$20+J38*(1-$B$20))) | L38: =IF(OR(H38="",K38=""),"",K38-H38)
F39: =Formulation!$B$20 | G39: =IF(E39="","",E39/F39) | H39: =IF(OR(G39="",$E$15=""),"",1-G39/$E$15) | J39: =IF(I39="","",(I39-$B$18)/($B$19-$B$18)) | K39: =IF(OR(J39="",$B$20=""),"",J39/($B$20+J39*(1-$B$20))) | L39: =IF(OR(H39="",K39=""),"",K39-H39)
... F42: =Formulation!$B$20 | G42: =IF(E42="","",E42/F42) | H42: =IF(OR(G42="",$E$15=""),"",1-G42/$E$15) | J42: =IF(I42="","",(I42-$B$18)/($B$19-$B$18)) | K42: =IF(OR(J42="",$B$20=""),"",J42/($B$20+J42*(1-$B$20))) | L42: =IF(OR(H42="",K42=""),"",K42-H42)

Sheet DSC_Isothermal
A1: DSC only — isothermal cure + residual scan (no reference scan, no FTIR) | J1: HOW TO USE — DSC_Isothermal (DSC only, one specimen)
A2: Paste the isothermal heat-flow export; Q(t) is integrated (trapezoid) and α(t) = Q(t)/ΔH_total, with ΔH_total = Q_iso + Q_residual by default. ▸ How to use this sheet: column J | J2: ↩ Back to the Guide
J3: Run
A4: Sample ID | B4: ISO-80 | J4: 1 Mix, load quickly, jump to the cure temperature and hold until the heat flow is flat.
A5: Isothermal temperature (°C) | B5: 80 | H5: Information only | J5: 2 Cool, then heat the same specimen through its residual exotherm (dynamic scan).
A6: Sample mass (mg) | B6: 9.5 | H6: If the export is in mW, divide by mass in mg → W/g (mW/mg = W/g) | J6: Enter
A7: Exotherm direction in export ▼ | B7: Exo up | H7: Sign convention of your instrument | J7: 3 Paste time (min) and heat flow (W/g) from A27 down — no gaps, up to 1000 points. Clear unused example rows.
A8: Baseline heat flow (W/g, same sign as export) | B8: 0.0005 | H8: Best: rerun the cured specimen at the same T, or an empty-pan run. Blank → last data point is taken as baseline | J8: Exported in mW? Divide by the sample mass in mg (mW/mg = W/g).
A9: Residual heat, dynamic scan after isothermal (J/g sample) | B9: 9.76 | H9: Cool after the isothermal, then scan through the residual exotherm | J9: 4 B7: exotherm direction of your instrument. B8: baseline heat flow, ideally from re-running the
A10: ΔH_total basis ▼ | B10: Isothermal + residual | H10: Isothermal + residual = one specimen, DSC only. Alternatives use DSC!E8 or the formulation | J10: cured specimen at the same temperature. Blank B8 = last point, valid only if cure had finished.
J11: 5 B9: residual heat from step 2 (J/g sample). B10: leave on Isothermal + residual.
A12: Calculated | J12: Read
A13: Data points | B13: =COUNT(A27:A1026) | H13: Data must start at row 27 with no gaps | J13: 6 B19 = conversion at the end of the hold; columns E–F = α(t) and dα/dt for every point.
A14: Baseline used (W/g) | B14: =IF(B8="",IF(B13=0,0,INDEX(B27:B1026,B13)),B8) | J14: 7 B21 compares the total heat with theory; B23 warns if the run ended before the reaction did.
A15: Sign factor | B15: =IF(B7="Exo down",-1,1) | J15: To plot α(t): select the filled rows of columns A and E, then Insert → Scatter.
A16: Isothermal heat, Q_iso (J/g sample) | B16: =IF(B13=0,"",INDEX(D27:D1026,B13)) | H16: Integrated net exotherm over the whole run | J16: Specimens
A17: Q_iso + Q_residual (J/g sample) | B17: =IF(B16="","",B16+B9) | J17: 5–10 mg of fresh mix in a hermetic pan, dropped into a cell already at the cure temperature.
A18: ΔH_total used (J/g sample) | B18: =IF(B10="Theoretical (formulation)",Formulation!B31,IF(B10="Measured reference",IF(DSC!E8="","",DSC!E8*Formulation!B20),B17)) | J18: ▸ Full preparation protocol for this sheet (Sample_Prep)
A19: α at end of isothermal = Q_iso / ΔH_total | B19: =IF(OR(B16="",B18=""),"",B16/B18)
A20: α from residual = 1 − Q_res / ΔH_total | B20: =IF(OR(B9="",B18=""),"",1-B9/B18) | H20: Identical to the row above when basis = Isothermal + residual | J20: Figure — 1 paste the isothermal export, 2 add the residual scan, 3 read α(t).
A21: (Q_iso + Q_res) / theoretical ΔH | B21: =IF(B17="","",B17/Formulation!B31) | H21: Heat balance; well below 100 % → heat lost before data collection began, or ΔH_urethane set too high
A22: End-of-run net heat flow, % of peak | B22: =IF(B13=0,"",INDEX(C27:C1026,B13)/MAX(C27:C1026))
A23: Run check | B23: =IF(B22="","",IF(B22>0.02,"Reaction still running at end of run — enter a measured baseline and the residual heat","OK"))
A24: The first ~0.5–1 min after loading is usually lost to thermal equilibration; that heat is missed by Q_iso but still counted in the heat-balance row.
A26: Time (min) | B26: Heat flow, as exported (W/g) | C26: Net exotherm (W/g) | D26: Cumulative heat Q(t) (J/g sample) | E26: α(t) | F26: dα/dt (min⁻¹)
A27: 0 | B27: 0.027167 | C27: =IF(B27="","",$B$15*(B27-$B$14)) | D27: =IF(A27="","",0) | E27: =IF(OR(D27="",$B$18=""),"",D27/$B$18) | F27: =IF(OR(C27="",$B$18=""),"",C27*60/$B$18)
A28: 3 | B28: 0.024233 | C28: =IF(B28="","",$B$15*(B28-$B$14)) | D28: =IF(OR(A28="",C28="",D27="",C27=""),"",D27+(C27+C28)/2*(A28-A27)*60) | E28: =IF(OR(D28="",$B$18=""),"",D28/$B$18) | F28: =IF(OR(C28="",$B$18=""),"",C28*60/$B$18)
A29: 6 | B29: 0.021759 | C29: =IF(B29="","",$B$15*(B29-$B$14)) | D29: =IF(OR(A29="",C29="",D28="",C28=""),"",D28+(C28+C29)/2*(A29-A28)*60) | E29: =IF(OR(D29="",$B$18=""),"",D29/$B$18) | F29: =IF(OR(C29="",$B$18=""),"",C29*60/$B$18)
A30: 9 | B30: 0.019652 | C30: =IF(B30="","",$B$15*(B30-$B$14)) | D30: =IF(OR(A30="",C30="",D29="",C29=""),"",D29+(C29+C30)/2*(A30-A29)*60) | E30: =IF(OR(D30="",$B$18=""),"",D30/$B$18) | F30: =IF(OR(C30="",$B$18=""),"",C30*60/$B$18)
A31: 12 | B31: 0.017843 | C31: =IF(B31="","",$B$15*(B31-$B$14)) | D31: =IF(OR(A31="",C31="",D30="",C30=""),"",D30+(C30+C31)/2*(A31-A30)*60) | E31: =IF(OR(D31="",$B$18=""),"",D31/$B$18) | F31: =IF(OR(C31="",$B$18=""),"",C31*60/$B$18)
A32: 15 | B32: 0.016279 | C32: =IF(B32="","",$B$15*(B32-$B$14)) | D32: =IF(OR(A32="",C32="",D31="",C31=""),"",D31+(C31+C32)/2*(A32-A31)*60) | E32: =IF(OR(D32="",$B$18=""),"",D32/$B$18) | F32: =IF(OR(C32="",$B$18=""),"",C32*60/$B$18)
A33: 18 | B33: 0.014918 | C33: =IF(B33="","",$B$15*(B33-$B$14)) | D33: =IF(OR(A33="",C33="",D32="",C32=""),"",D32+(C32+C33)/2*(A33-A32)*60) | E33: =IF(OR(D33="",$B$18=""),"",D33/$B$18) | F33: =IF(OR(C33="",$B$18=""),"",C33*60/$B$18)
A34: 21 | B34: 0.013725 | C34: =IF(B34="","",$B$15*(B34-$B$14)) | D34: =IF(OR(A34="",C34="",D33="",C33=""),"",D33+(C33+C34)/2*(A34-A33)*60) | E34: =IF(OR(D34="",$B$18=""),"",D34/$B$18) | F34: =IF(OR(C34="",$B$18=""),"",C34*60/$B$18)
A35: 24 | B35: 0.012674 | C35: =IF(B35="","",$B$15*(B35-$B$14)) | D35: =IF(OR(A35="",C35="",D34="",C34=""),"",D34+(C34+C35)/2*(A35-A34)*60) | E35: =IF(OR(D35="",$B$18=""),"",D35/$B$18) | F35: =IF(OR(C35="",$B$18=""),"",C35*60/$B$18)
A36: 27 | B36: 0.011744 | C36: =IF(B36="","",$B$15*(B36-$B$14)) | D36: =IF(OR(A36="",C36="",D35="",C35=""),"",D35+(C35+C36)/2*(A36-A35)*60) | E36: =IF(OR(D36="",$B$18=""),"",D36/$B$18) | F36: =IF(OR(C36="",$B$18=""),"",C36*60/$B$18)
A37: 30 | B37: 0.010917 | C37: =IF(B37="","",$B$15*(B37-$B$14)) | D37: =IF(OR(A37="",C37="",D36="",C36=""),"",D36+(C36+C37)/2*(A37-A36)*60) | E37: =IF(OR(D37="",$B$18=""),"",D37/$B$18) | F37: =IF(OR(C37="",$B$18=""),"",C37*60/$B$18)
A38: 33 | B38: 0.010177 | C38: =IF(B38="","",$B$15*(B38-$B$14)) | D38: =IF(OR(A38="",C38="",D37="",C37=""),"",D37+(C37+C38)/2*(A38-A37)*60) | E38: =IF(OR(D38="",$B$18=""),"",D38/$B$18) | F38: =IF(OR(C38="",$B$18=""),"",C38*60/$B$18)
A39: 36 | B39: 0.009514 | C39: =IF(B39="","",$B$15*(B39-$B$14)) | D39: =IF(OR(A39="",C39="",D38="",C38=""),"",D38+(C38+C39)/2*(A39-A38)*60) | E39: =IF(OR(D39="",$B$18=""),"",D39/$B$18) | F39: =IF(OR(C39="",$B$18=""),"",C39*60/$B$18)
... A147: 360 | B147: 0.000897 | C147: =IF(B147="","",$B$15*(B147-$B$14)) | D147: =IF(OR(A147="",C147="",D146="",C146=""),"",D146+(C146+C147)/2*(A147-A146)*60) | E147: =IF(OR(D147="",$B$18=""),"",D147/$B$18) | F147: =IF(OR(C147="",$B$18=""),"",C147*60/$B$18)
C148: =IF(B148="","",$B$15*(B148-$B$14)) | D148: =IF(OR(A148="",C148="",D147="",C147=""),"",D147+(C147+C148)/2*(A148-A147)*60) | E148: =IF(OR(D148="",$B$18=""),"",D148/$B$18) | F148: =IF(OR(C148="",$B$18=""),"",C148*60/$B$18)
...

Sheet FTIR
A1: FTIR — NCO band (~2270 cm⁻¹) normalised to an internal reference | O1: HOW TO USE — FTIR
A2: α = 1 − R/R0, R = A_NCO/A_ref. Row 11 must be the t = 0 spectrum. ▸ How to use this sheet: column O | O2: ↩ Back to the Guide
O3: Measure
A4: NCO band / integration limits | B4: 2270 cm⁻¹ (integrate 2230–2300) | O4: 1 Record the freshly mixed material first. It goes in row 11 and defines R0.
A5: Reference band | B5: 2870–2970 cm⁻¹ C–H stretch | O5: 2 Keep sampling identical at every time point: crystal, pressure, number of scans, resolution.
A6: Sampling mode | B6: ATR, diamond | O6: Integrate
A7: Reference-band drift tolerance | B7: 0.1 | C7: Flags a sample whose A_ref differs from t = 0 by more than this (contact/thickness change) | O7: 3 A_NCO (column D): NCO band, ~2230–2300 cm⁻¹, with a local linear baseline.
O8: 4 A_ref (column E): a band that does not change on cure — C–H 2850–2990 cm⁻¹, or ~1595 cm⁻¹
